/**
 * Tests for ErrorBoundary component
 */

import { render, screen } from '@testing-library/react';
import { afterAll, beforeAll, describe, expect, it, vi } from 'vitest';
import { ErrorBoundary } from '@/components/ErrorBoundary';

// Component that throws an error
const ThrowError = ({ shouldThrow }: { shouldThrow: boolean }) => {
  if (shouldThrow) {
    throw new Error('Test error message');
  }
  return <div>No error</div>;
};

describe('ErrorBoundary', () => {
  // Suppress console.error for these tests
  const originalError = console.error;
  beforeAll(() => {
    console.error = vi.fn();
  });

  afterAll(() => {
    console.error = originalError;
  });

  it('renders children when there is no error', () => {
    render(
      <ErrorBoundary>
        <div>Child content</div>
      </ErrorBoundary>
    );

    expect(screen.getByText('Child content')).toBeInTheDocument();
  });

  it('renders error UI when child component throws', () => {
    render(
      <ErrorBoundary>
        <ThrowError shouldThrow={true} />
      </ErrorBoundary>
    );

    expect(screen.getByText(/something went wrong/i)).toBeInTheDocument();
  });

  it('displays error message when available', () => {
    render(
      <ErrorBoundary>
        <ThrowError shouldThrow={true} />
      </ErrorBoundary>
    );

    expect(screen.getByText(/test error message/i)).toBeInTheDocument();
  });

  it('can recover and show children again when error is cleared', () => {
    const { rerender } = render(
      <ErrorBoundary>
        <ThrowError shouldThrow={true} />
      </ErrorBoundary>
    );

    expect(screen.getByText(/something went wrong/i)).toBeInTheDocument();

    // Rerender with no error
    rerender(
      <ErrorBoundary>
        <ThrowError shouldThrow={false} />
      </ErrorBoundary>
    );

    // Note: React error boundaries don't automatically recover
    // This test documents current behavior
    expect(screen.getByText(/something went wrong/i)).toBeInTheDocument();
  });
});
